Workbook
Name LISTA_N_SERIES: 'BUSQUEDA'!$I$2:$I$3993

Sheet TARJETA DIGITAL
D2: TARJETA DE INSPECCIÓN DE EXTINTORES NORMA NTP 833.030-2001
B6: EL SERVICIO VENCE EL AÑO Y MES PERFORADO EN EL STICKER DE CONTROL ADHERIDO AL EXTINTOR
B9: TARJETA DE INSPECCIÓN N° | D9: =IFERROR(VLOOKUP(TRIM(H12),BUSQUEDA!$A$2:$G$5568,2,FALSE),"")
B10: CLIENTE | D10: =IFERROR(VLOOKUP(TRIM(H12),BUSQUEDA!$A$2:$G$5568,3,FALSE),"")
B11: DIRECCIÓN | D11: =IFERROR(VLOOKUP(TRIM(H12),BUSQUEDA!$A$2:$G$5568,4,FALSE),"")
B12: EXTINTOR N° | D12: =IFERROR(VLOOKUP(TRIM(H12),BUSQUEDA!$A$2:$G$5568,5,FALSE),"") | F12: N° DE SERIE
B13: CAPACIDAD DE CARGA | D13: =IFERROR(VLOOKUP(TRIM(H12),BUSQUEDA!$A$2:$G$5568,6,FALSE),"") | F13: TIPO | H13: =IFERROR(VLOOKUP(TRIM(H12),BUSQUEDA!$A$2:$G$5568,7,FALSE),"")
B15: FECHA | E15: INSPECTOR | H15: OBSERVACIONES
B16: =TODAY() | H16: NINGUNA
B17: =TODAY() | H17: NINGUNA
B18: =TODAY() | H18: NINGUNA
B19: =TODAY() | H19: NINGUNA
B20: =TODAY() | H20: NINGUNA
B21: =TODAY() | H21: NINGUNA
B22: =TODAY() | H22: NINGUNA
B23: =TODAY() | H23: NINGUNA
B24: =TODAY() | H24: NINGUNA
B25: =TODAY() | H25: NINGUNA
B26: =TODAY() | H26: NINGUNA
B28: FECHA DE VENCIMIENTO DE RECARGA / PRÓXIMO MANTENIMIENTO | G28: =TODAY()
B29: FECHA DE PRÓXIMA PRUEBA HIDROSTÁTICA | G29: =EDATE(G28,60)
B31: GARANTÍA DE FUNCIONAMIENTO 12 MESES
B34: DISTRIBUIDO POR GEXSA SOLUTIONS | VENTA, MANTENIMIENTO Y RECARGA DE EXTINTORES AV. TÚPAC AMARU N° 7459 – AÑO NUEVO – COMAS – LIMA | (01) 397-9709
B38: DESCRIPCIÓN DE OBSERVACIONES
B40: 1. MAL UBICADO | F40: 2. ACCESO OBSTRUIDO
B41: 3. ZONA Y/O EXTINTOR NO NUMERADOS | F41: 4. CARECE/ILEGIBLE PICTOGRAMA DE CLASE DE FUEGO
B42: 5. CARECE/ILEGIBLE DE FORMA DE USO | F42: 6. CARECE/ILEGIBLE ETIQUETA DE RECARGA
B43: 7. NO IDENTIFICA TIPO DE CARGA, N° DE PARTE Y/O CONCENTRACIÓN DEL AGENTE IGNÍFUGO ACTIVO | F43: 8. COLGADOR AUSENTE O INADECUADO
B44: 9. SIN PASADOR Y/O PRECINTO DE SEGURIDAD | F44: 10. MANÓMETRO CON PRESIÓN INADECUADA Y/O DAÑADA
B45: 11. MANIJA DE ACARREO Y/O PALANCA DE ACTIVACIÓN DE CABEZAL O PISTOLA AUSENTE O DAÑADA | F45: 12. MANGUERA DAÑADA O AUSENTE
B46: 13. TOBERA, PITÓN O PISTOLA DAÑADA O AUSENTE | F46: 14. ABRAZADERA O SUJETADOR DE MANGUERA INADECUADO, DAÑADO O AUSENTE
B47: 15. CILINDRO / BOTELLA / CARTUCHO IMPULSOR EN MAL ESTADO | F47: 16. PINTURA DETERIORADA EN: CILINDRO / BOTELLA / CARTUCHO IMPULSOR
B48: 17. OTROS (INDICAR):

Sheet CATALOGO
A1: OBSERVACIONES DE INSPECCIÓN | B1: ESTADO
A2: NINGUNA | B2: SIN OBSERVACIONES
A3: 1. MAL UBICADO | B3: CON OBSERVACIÓN
A4: 2. ACCESO OBSTRUIDO | B4: NO CONFORME
A5: 3. ZONA Y/O EXTINTOR NO NUMERADOS
A6: 4. CARECE/ILEGIBLE PICTOGRAMA DE CLASE DE FUEGO
A7: 5. CARECE/ILEGIBLE DE FORMA DE USO
A8: 6. CARECE/ILEGIBLE ETIQUETA DE RECARGA
A9: 7. NO IDENTIFICA TIPO DE CARGA, N° DE PARTE Y/O CONCENTRACIÓN DEL AGENTE IGNÍFUGO ACTIVO
A10: 8. COLGADOR AUSENTE O INADECUADO
A11: 9. SIN PASADOR Y/O PRECINTO DE SEGURIDAD
A12: 10. MANÓMETRO CON PRESIÓN INADECUADA Y/O DAÑADA
A13: 11. MANIJA DE ACARREO Y/O PALANCA DE ACTIVACIÓN DE CABEZAL O PISTOLA AUSENTE O DAÑADA
A14: 12. MANGUERA DAÑADA O AUSENTE
A15: 13. TOBERA, PITÓN O PISTOLA DAÑADA O AUSENTE
A16: 14. ABRAZADERA O SUJETADOR DE MANGUERA INADECUADO, DAÑADO O AUSENTE
... A19: 17. OTROS (INDICAR):

Sheet INSTRUCCIONES
A1: TARJETA DIGITAL GEXSA – PRIMERA VERSIÓN
A2: Objetivo | B2: Plantilla compatible con Excel/Google Sheets para digitalizar la tarjeta física de inspección.
A3: Editable por el cliente | B3: Solo las 11 filas mensuales: FECHA, INSPECTOR y OBSERVACIONES.
A4: Observaciones | B4: La columna OBSERVACIONES usa una lista desplegable con las 17 opciones observadas en la tarjeta física.
A5: Datos del extintor | B5: Cliente, dirección, extintor, serie, capacidad y tipo quedan reservados para vincularlos después con la base GEXSA.
A6: Siguiente etapa | B6: Conectar esta plantilla a la base de datos para que, al ingresar/seleccionar el N° de serie, se complete automáticamente la ficha.
A7: QR | B7: El QR no debe apuntar directamente al PDF. En la siguiente etapa apuntará a una página con dos botones: VER CERTIFICADO PDF y LLENAR TARJETA DE INSPECCIÓN.
A8: Importante | B8: La protección de rangos se debe terminar en Google Sheets después de subir esta plantilla, para definir exactamente qué celdas puede editar el cliente.

Sheet BASE_EQUIPOS
A1: CODIGO_CERTIFICADO | B1: CLIENTE | C1: RUC | D1: DIRECCION | E1: FECHA_CERTIFICADO | F1: SERVICIO | G1: ITEM | H1: CAPACIDAD | I1: PRUEBA_HIDROSTATICA | J1: FECHA_FAB | K1: FECHA_CARGA | L1: FECHA_VCMTO | M1: AGENTE_CLASE | N1: UBICACION_SERIE | O1: SERVICIO_ITEM | P1: CLAVE_SERIE
B2: PERU MASIVO S.A. | C2: 20492392031 | D2: AV. LOS INCAS CDRA. 4 PATIO NORTE - COMAS | E2: Lima, 16 de Marzo de 2023 | F2: la Recarga y mantenimiento | G2: 1 | H2: 06 KG | I2: 2021 | J2: 2009 | K2: MARZO 2023 | L2: MARZO 2024 | M2: P.Q.S TIPO ABC AL 90% NACIONAL | N2: 11 / 000398 | O2: R | P2: =TRIM(N2)
B3: PERU MASIVO S.A. | C3: 20492392031 | D3: AV. LOS INCAS CDRA. 4 PATIO NORTE - COMAS | E3: Lima, 16 de Marzo de 2023 | F3: la Recarga y mantenimiento | G3: 2 | H3: 06 KG | I3: 2022 | J3: 2009 | K3: MARZO 2023 | L3: MARZO 2024 | M3: P.Q.S TIPO ABC AL 90% NACIONAL | N3: 275 / 000693 | O3: R | P3: =TRIM(N3)
B4: PERU MASIVO S.A. | C4: 20492392031 | D4: AV. LOS INCAS CDRA. 4 PATIO NORTE - COMAS | E4: Lima, 16 de Marzo de 2023 | F4: la Recarga y mantenimiento | G4: 3 | H4: 06 KG | I4: 2021 | J4: 2009 | K4: MARZO 2023 | L4: MARZO 2024 | M4: P.Q.S TIPO ABC AL 90% NACIONAL | N4: 189 / 000999 | O4: R | P4: =TRIM(N4)
B5: PERU MASIVO S.A. | C5: 20492392031 | D5: AV. LOS INCAS CDRA. 4 PATIO NORTE - COMAS | E5: Lima, 16 de Marzo de 2023 | F5: la Recarga y mantenimiento | G5: 4 | H5: 06 KG | I5: 2021 | J5: 2010 | K5: MARZO 2023 | L5: MARZO 2024 | M5: P.Q.S TIPO ABC AL 90% NACIONAL | N5: 260 / 000498 | O5: R | P5: =TRIM(N5)
B6: PERU MASIVO S.A. | C6: 20492392031 | D6: AV. LOS INCAS CDRA. 4 PATIO NORTE - COMAS | E6: Lima, 16 de Marzo de 2023 | F6: la Recarga y mantenimiento | G6: 5 | H6: 06 KG | I6: 2022 | J6: 2010 | K6: MARZO 2023 | L6: MARZO 2024 | M6: P.Q.S TIPO ABC AL 90% NACIONAL | N6: 185 / 000613 | O6: R | P6: =TRIM(N6)
B7: PERU MASIVO S.A. | C7: 20492392031 | D7: AV. LOS INCAS CDRA. 4 PATIO NORTE - COMAS | E7: Lima, 16 de Marzo de 2023 | F7: la Recarga y mantenimiento | G7: 6 | H7: 06 KG | I7: 2020 | J7: 2009 | K7: MARZO 2023 | L7: MARZO 2024 | M7: P.Q.S TIPO ABC AL 90% NACIONAL | N7: 07 / 001500 | O7: R | P7: =TRIM(N7)
B8: PERU MASIVO S.A. | C8: 20492392031 | D8: AV. LOS INCAS CDRA. 4 PATIO NORTE - COMAS | E8: Lima, 16 de Marzo de 2023 | F8: la Recarga y mantenimiento | G8: 7 | H8: 06 KG | I8: 2019 | J8: 2010 | K8: MARZO 2023 | L8: MARZO 2024 | M8: P.Q.S TIPO ABC AL 90% NACIONAL | N8: 140 / 006500 | O8: R | P8: =TRIM(N8)
B9: PERU MASIVO S.A. | C9: 20492392031 | D9: AV. LOS INCAS CDRA. 4 PATIO NORTE - COMAS | E9: Lima, 16 de Marzo de 2023 | F9: la Recarga y mantenimiento | G9: 8 | H9: 06 KG | I9: 2020 | J9: 2009 | K9: MARZO 2023 | L9: MARZO 2024 | M9: P.Q.S TIPO ABC AL 90% NACIONAL | N9: S/N / 000039 | O9: R | P9: =TRIM(N9)
B10: PERU MASIVO S.A. | C10: 20492392031 | D10: AV. LOS INCAS CDRA. 4 PATIO NORTE - COMAS | E10: Lima, 16 de Marzo de 2023 | F10: la Recarga y mantenimiento | G10: 9 | H10: 06 KG | I10: 2021 | J10: S/N | K10: MARZO 2023 | L10: MARZO 2024 | M10: P.Q.S TIPO ABC AL 90% NACIONAL | N10: 314 / 002909 | O10: R | P10: =TRIM(N10)
A11: CO-001012 | B11: IGLESIA METODISTA DEL PERU – LA FLORIDA | D11: CALLE 13 N° 195 Urb. La Florida – Rímac | E11: Lima,19 de Julio de 2022 | F11: la Recarga y mantenimiento | G11: - | H11: 06 KG | I11: 2024 | J11: 2019 | K11: JULIO 2022 | L11: JULIO 2023 | M11: P.Q.S. AL 90% TIPO ABC | N11: 01/000551 | O11: R | P11: =TRIM(N11)
A12: CO-001012 | B12: IGLESIA METODISTA DEL PERU – LA FLORIDA | D12: CALLE 13 N° 195 Urb. La Florida – Rímac | E12: Lima,19 de Julio de 2022 | F12: la Recarga y mantenimiento | G12: 2 | H12: 06 KG | I12: 2024 | J12: 2019 | K12: JULIO 2022 | L12: JULIO 2023 | M12: P.Q.S./ABC | N12: 02/000674 | O12: R | P12: =TRIM(N12)
A13: CO-001013 | B13: IGLESIA METODISTA DEL PERU – LA FLORIDA | D13: CALLE 13 N° 195 Urb. La Florida – Rímac | E13: Lima,19 de Julio de 2023 | F13: la Recarga y mantenimiento | G13: 1 | H13: 6 KG | I13: 2027 | J13: 2022 | K13: JULIO 2022 | L13: JULIO 2023 | M13: P.Q.S. AL 90% TIPO ABC | N13: 03/015357 | P13: =TRIM(N13)
A14: CO-001018 | B14: NEGOPEP SRL. | C14: 20194160624 | D14: Av. Tupac Amaru 4777 - Comas | E14: Lima,27 de Julio de 2023 | F14: la Recarga y mantenimiento | G14: - | H14: 06 KG | I14: 2022 | J14: 2005 | K14: JULIO 2022 | L14: JULIO 2023 | M14: P.Q.S. AL 90% TIPO ABC | N14: 01/002696 | O14: R | P14: =TRIM(N14)
A15: CO-001019 | B15: JOSE CARLOS CORANTE MENDOZA | C15: 70521103 | D15: A0A 217 | E15: Lima, 22 de Agosto de 2022 | F15: la venta | G15: - | H15: 04 KG | I15: 2027 | J15: 2022 | K15: AGOSTO 2022 | L15: AGOSTO 2023 | M15: P.Q.S. TIPO ABC | N15: 01/617327 | O15: V | P15: =TRIM(N15)
A16: CO-001020 | B16: DIAZ MALDONADO DOWNNIG GUSTAVO | C16: 45099295 | D16: D6L 070 | E16: Lima, 24 de Agosto de 2023 | F16: la venta | G16: - | H16: 04 KG | I16: 2027 | J16: 2022 | K16: AGOSTO 2022 | L16: AGOSTO 2023 | M16: P.Q.S. TIPO ABC | N16: 01/617674 | O16: V | P16: =TRIM(N16)
A17: CO-001021 | B17: DANY DAVID LEON NAVARRO | C17: 41554444 | D17: D5B494 | E17: Lima, 24 de Agosto de 2022 | F17: la Recarga y mantenimiento | G17: - | H17: 02 KG | I17: VIGENTE | J17: S/N | K17: AGOSTO 2022 | L17: AGOSTO 2023 | M17: P.Q.S. TIPO ABC | N17: S/N | O17: R | P17: =TRIM(N17)
A18: CO-001022 | B18: JHOEL OCAÑA MAGUIÑA | C18: 10103994441 | D18: JR UNIÓN N° 200 URB SAN FELIPE - COMAS | E18: Lima, 29 de Agosto de 2022 | F18: la Recarga y mantenimiento | G18: - | H18: 06 KG | I18: VIGENTE | J18: 2018 | K18: AGOSTO 2022 | L18: AGOSTO 2023 | M18: P.Q.S. TIPO ABC | N18: 01/185 | O18: R | P18: =TRIM(N18)
A19: CO-001022 | B19: JHOEL OCAÑA MAGUIÑA | C19: 10103994441 | D19: JR UNIÓN N° 200 URB SAN FELIPE - COMAS | E19: Lima, 29 de Agosto de 2022 | F19: la Recarga y mantenimiento | G19: - | H19: 06 KG | I19: VIGENTE | J19: 2018 | K19: AGOSTO 2022 | L19: AGOSTO 2023 | M19: P.Q.S. TIPO ABC | N19: 01/3149 | O19: R | P19: =TRIM(N19)
A20: CO-001023 | B20: CHATARRERIA AARON | D20: Pasaje 23 MZ J LT 15 Año nuevo - Comas | E20: Lima, 01 de Setiembre de 2022 | F20: la Recarga y mantenimiento | G20: - | H20: 06 KG | I20: 2027 | J20: 2014 | K20: SETIEMBRE 2022 | L20: SETIEMBRE 2023 | M20: P.Q.S. TIPO ABC | N20: 01/003505 | O20: R | P20: =TRIM(N20)
A21: CO-001023 | B21: CHATARRERIA AARON | D21: Pasaje 23 MZ J LT 15 Año nuevo - Comas | E21: Lima, 01 de Setiembre de 2022 | F21: la Recarga y mantenimiento | G21: - | H21: 06 KG | I21: 2023 | J21: 2018 | K21: SETIEMBRE 2022 | L21: SETIEMBRE 2023 | M21: P.Q.S. TIPO ABC | N21: 02/003501 | O21: R | P21: =TRIM(N21)
A22: CO-001024 | B22: FRANCISCO MONTALVO BAÑON | C22: 45485735 | D22: ATK-907 | E22: Lima, 02 de Setiembre de 2022 | F22: la Recarga y mantenimiento | G22: - | H22: 09 KG | I22: VIGENTE | J22: 2015 | K22: SETIEMBRE 2022 | L22: SETIEMBRE 2023 | M22: P.Q.S. TIPO ABC | N22: 01/000243 | O22: R | P22: =TRIM(N22)
A23: CO-001025 | B23: FIDENCIO ALBUJAR ACUÑA | C23: 23096045 | D23: ARH 710 | E23: Lima, 05 de Setiembre de 2022 | F23: la Recarga y mantenimiento | G23: - | H23: 04 KG | I23: VIGENTE | J23: 2013 | K23: SETIEMBRE 2022 | L23: SETIEMBRE 2023 | M23: P.Q.S. TIPO ABC | N23: 01/000306 | O23: R | P23: =TRIM(N23)
A24: CO-001026 | B24: JOSIAS ALCIDES TARAZONA BACILIO | C24: 70215943 | E24: Lima, 07 de Setiembre de 2022 | F24: la Recarga y mantenimiento | G24: - | H24: 06 KG | I24: 2023 | J24: 2018 | K24: SETIEMBRE 2022 | L24: SETIEMBRE 2023 | M24: P.Q.S. TIPO ABC | N24: 01/021024 | O24: R | P24: =TRIM(N24)
A25: CO-001027 | B25: EDWIN CUEVA | D25: AV TUPAC AMARU 3931 | E25: Lima, 09 de Setiembre de 2022 | F25: la Recarga y mantenimiento | G25: - | H25: 02 KG | I25: VIGENTE | J25: 2005 | K25: SETIEMBRE 2022 | L25: SETIEMBRE 2023 | M25: P.Q.S. TIPO ABC | N25: 01/001391 | O25: R | P25: =TRIM(N25)
A26: CO-001028 | B26: DENNIS MIGUEL ALTUNA ANDIA | C26: 09990860 | D26: A1D-095 | E26: Lima, 09 de Setiembre de 2022 | F26: la Venta | G26: - | H26: 02 KG | I26: 2027 | J26: 2022 | K26: SETIEMBRE 2022 | L26: SETIEMBRE 2023 | M26: P.Q.S. TIPO ABC | N26: 01/000858 | O26: V | P26: =TRIM(N26)
A27: CO-001029 | B27: COOPERATIVA DE SERVICIOS ESPECIALES DOS DE MAYO | D27: JR. PIURA N° 166 SAN FELIPE - COMAS | E27: Lima, 09 de Setiembre de 2022 | F27: la Recarga y mantenimiento | G27: - | H27: 09 KG | I27: 2023 | J27: 2018 | K27: SETIEMBRE 2022 | L27: SETIEMBRE 2023 | M27: P.Q.S. TIPO ABC | N27: 01/000254 | O27: R | P27: =TRIM(N27)
A28: CO-001030 | B28: AGFA COLOR/ SRA CRUZ SALAZAR | D28: AV CAUDIVILLA MZ G LT 10 URB SANTA ROSA DE PUNCHAUCA | E28: Lima, 09 de Setiembre de 2022 | F28: la Recarga y mantenimiento | G28: - | H28: 06 KG | I28: 2026 | J28: 2008 | K28: SETIEMBRE 2022 | L28: SETIEMBRE 2023 | M28: P.Q.S. TIPO ABC | N28: 01/003536 | O28: R | P28: =TRIM(N28)
A29: CO-001031 | B29: LOLO WILLAN RODRIGUEZ TOMAS | C29: 44508485 | D29: AV TUPAC AMARU 4668 MZ A LT 7 PUEBLO JOVEN LA PAMPA - COMAS | E29: Lima, 12 de Setiembre de 2022 | F29: la venta | G29: - | H29: 06 KG | I29: 2027 | J29: 2022 | K29: SETIEMBRE 2022 | L29: SETIEMBRE 2023 | M29: P.Q.S. TIPO ABC | N29: 01/153603 | O29: v | P29: =TRIM(N29)
A30: CO-001032 | B30: MELITON ALZAMORA | C30: 06272406 | D30: F3S-415 | E30: Lima, 12 de Setiembre de 2022 | F30: la Recarga y mantenimiento | G30: - | H30: 02 KG | I30: VIGENTE | J30: 2014 | K30: SETIEMBRE 2022 | L30: SETIEMBRE 2023 | M30: P.Q.S. TIPO ABC | N30: 01/001014 | O30: R | P30: =TRIM(N30)
A31: CO-001033 | B31: LUZ MARIA PROA VILCHEZ | D31: JR TARAPACA N° 181 COLLIQUE- COMAS | E31: Lima, 12 de Setiembre de 2022 | F31: la Recarga y mantenimiento | G31: - | H31: 04 KG | I31: 2027 | J31: 2011 | K31: SETIEMBRE 2022 | L31: SETIEMBRE 2023 | M31: P.Q.S. TIPO ABC | N31: 01/000011 | O31: R | P31: =TRIM(N31)
A32: CO-001034 | B32: MARIA SOLORZANO | D32: VILLA VIOLETA MZ G LT 01 | E32: Lima, 13 de Setiembre de 2022 | F32: la Recarga y mantenimiento | G32: - | H32: 06 KG | I32: VIGENTE | J32: 2005 | K32: SETIEMBRE 2022 | L32: SETIEMBRE 2023 | M32: P.Q.S. TIPO ABC | N32: 01/001415 | O32: R | P32: =TRIM(N32)
A33: CO-001035 | B33: MARIA CUCICHE | D33: MERCADO AÑO NUEVO - PUESTO 111 | E33: Lima, 15 de Setiembre de 2022 | F33: la Recarga y mantenimiento | G33: - | H33: 06 KG | I33: VIGENTE | J33: - | K33: SETIEMBRE 2022 | L33: SETIEMBRE 2023 | M33: P.Q.S. TIPO ABC | N33: S/N | O33: R | P33: =TRIM(N33)
A34: CO-001036 | B34: CELEDONIO PAJUELO | D34: MERCADO AÑO NUEVO - PUESTO 110 | E34: Lima, 15 de Setiembre de 2022 | F34: la Recarga y mantenimiento | G34: - | H34: 06 KG | I34: VIGENTE | J34: - | K34: SETIEMBRE 2022 | L34: SETIEMBRE 2023 | M34: P.Q.S. TIPO ABC | N34: 01/002910 | O34: R | P34: =TRIM(N34)
A35: CO-001037 | B35: GLADIS CARDENAS | D35: MERCADO AÑO NUEVO - PUESTO 22 | E35: Lima, 15 de Setiembre de 2022 | F35: la Recarga y mantenimiento | G35: - | H35: 06 KG | I35: VIGENTE | J35: - | K35: SETIEMBRE 2022 | L35: SETIEMBRE 2023 | M35: P.Q.S. TIPO ABC | N35: S/N | O35: R | P35: =TRIM(N35)
A36: CO-001038 | B36: KEVIN ALVARADO | D36: MERCADO AÑO NUEVO - PUESTO 163 | E36: Lima, 15 de Setiembre de 2022 | F36: la Recarga y mantenimiento | G36: - | H36: 06 KG | I36: VIGENTE | J36: - | K36: SETIEMBRE 2022 | L36: SETIEMBRE 2023 | M36: P.Q.S. TIPO ABC | N36: 01/000115 | O36: R | P36: =TRIM(N36)
A37: CO-001039 | B37: SANTOS RODRIGUEZ | D37: MERCADO AÑO NUEVO - PUESTO 167 | E37: Lima, 15 de Setiembre de 2022 | F37: la Recarga y mantenimiento | G37: - | H37: 04 KG | I37: 2025 | J37: 2020 | K37: SETIEMBRE 2022 | L37: SETIEMBRE 2023 | M37: P.Q.S. TIPO ABC | N37: 01/518004 | O37: R | P37: =TRIM(N37)
A38: CO-001040 | B38: MAGDALENA TIPULA | D38: MERCADO AÑO NUEVO - PUESTO 108 | E38: Lima, 15 de Setiembre de 2022 | F38: la Recarga y mantenimiento | G38: - | H38: 06 KG | I38: VIGENTE | J38: - | K38: SETIEMBRE 2022 | L38: SETIEMBRE 2023 | M38: P.Q.S. TIPO ABC | N38: 01/001241 | O38: R | P38: =TRIM(N38)
A39: CO-001041 | B39: ROCIO SULCE | D39: MERCADO AÑO NUEVO - PUESTO 104 | E39: Lima, 15 de Setiembre de 2022 | F39: la Recarga y mantenimiento | G39: - | H39: 06 KG | I39: VIGENTE | J39: 2007 | K39: SETIEMBRE 2022 | L39: SETIEMBRE 2023 | M39: P.Q.S. TIPO ABC | N39: 01/010204 | O39: R | P39: =TRIM(N39)
A40: CO-001042 | B40: ANA RODRIGUEZ | D40: MERCADO AÑO NUEVO - PUESTO 103 | E40: Lima, 15 de Setiembre de 2022 | F40: la Recarga y mantenimiento | G40: - | H40: 06 KG | I40: 2025 | J40: 2020 | K40: SETIEMBRE 2022 | L40: SETIEMBRE 2023 | M40: P.Q.S. TIPO ABC | N40: 01/8001287 | O40: R | P40: =TRIM(N40)
...

Sheet BUSQUEDA
A1: CLAVE_SERIE | B1: TARJETA | C1: CLIENTE | D1: DIRECCION | E1: EXTINTOR_N | F1: CAPACIDAD | G1: TIPO | I1: LISTA_SERIES
A2: =TRIM(BASE_EQUIPOS!N2) | B2: =BASE_EQUIPOS!A2 | C2: =BASE_EQUIPOS!B2 | D2: =BASE_EQUIPOS!D2 | E2: =BASE_EQUIPOS!G2 | F2: =BASE_EQUIPOS!H2 | G2: =BASE_EQUIPOS!M2 | I2: 11 / 000398
A3: =TRIM(BASE_EQUIPOS!N3) | B3: =BASE_EQUIPOS!A3 | C3: =BASE_EQUIPOS!B3 | D3: =BASE_EQUIPOS!D3 | E3: =BASE_EQUIPOS!G3 | F3: =BASE_EQUIPOS!H3 | G3: =BASE_EQUIPOS!M3 | I3: 275 / 000693
A4: =TRIM(BASE_EQUIPOS!N4) | B4: =BASE_EQUIPOS!A4 | C4: =BASE_EQUIPOS!B4 | D4: =BASE_EQUIPOS!D4 | E4: =BASE_EQUIPOS!G4 | F4: =BASE_EQUIPOS!H4 | G4: =BASE_EQUIPOS!M4 | I4: 189 / 000999
A5: =TRIM(BASE_EQUIPOS!N5) | B5: =BASE_EQUIPOS!A5 | C5: =BASE_EQUIPOS!B5 | D5: =BASE_EQUIPOS!D5 | E5: =BASE_EQUIPOS!G5 | F5: =BASE_EQUIPOS!H5 | G5: =BASE_EQUIPOS!M5 | I5: 260 / 000498
A6: =TRIM(BASE_EQUIPOS!N6) | B6: =BASE_EQUIPOS!A6 | C6: =BASE_EQUIPOS!B6 | D6: =BASE_EQUIPOS!D6 | E6: =BASE_EQUIPOS!G6 | F6: =BASE_EQUIPOS!H6 | G6: =BASE_EQUIPOS!M6 | I6: 185 / 000613
A7: =TRIM(BASE_EQUIPOS!N7) | B7: =BASE_EQUIPOS!A7 | C7: =BASE_EQUIPOS!B7 | D7: =BASE_EQUIPOS!D7 | E7: =BASE_EQUIPOS!G7 | F7: =BASE_EQUIPOS!H7 | G7: =BASE_EQUIPOS!M7 | I7: 07 / 001500
A8: =TRIM(BASE_EQUIPOS!N8) | B8: =BASE_EQUIPOS!A8 | C8: =BASE_EQUIPOS!B8 | D8: =BASE_EQUIPOS!D8 | E8: =BASE_EQUIPOS!G8 | F8: =BASE_EQUIPOS!H8 | G8: =BASE_EQUIPOS!M8 | I8: 140 / 006500
A9: =TRIM(BASE_EQUIPOS!N9) | B9: =BASE_EQUIPOS!A9 | C9: =BASE_EQUIPOS!B9 | D9: =BASE_EQUIPOS!D9 | E9: =BASE_EQUIPOS!G9 | F9: =BASE_EQUIPOS!H9 | G9: =BASE_EQUIPOS!M9 | I9: S/N / 000039
A10: =TRIM(BASE_EQUIPOS!N10) | B10: =BASE_EQUIPOS!A10 | C10: =BASE_EQUIPOS!B10 | D10: =BASE_EQUIPOS!D10 | E10: =BASE_EQUIPOS!G10 | F10: =BASE_EQUIPOS!H10 | G10: =BASE_EQUIPOS!M10 | I10: 314 / 002909
A11: =TRIM(BASE_EQUIPOS!N11) | B11: =BASE_EQUIPOS!A11 | C11: =BASE_EQUIPOS!B11 | D11: =BASE_EQUIPOS!D11 | E11: =BASE_EQUIPOS!G11 | F11: =BASE_EQUIPOS!H11 | G11: =BASE_EQUIPOS!M11 | I11: 01/000551
A12: =TRIM(BASE_EQUIPOS!N12) | B12: =BASE_EQUIPOS!A12 | C12: =BASE_EQUIPOS!B12 | D12: =BASE_EQUIPOS!D12 | E12: =BASE_EQUIPOS!G12 | F12: =BASE_EQUIPOS!H12 | G12: =BASE_EQUIPOS!M12 | I12: 02/000674
A13: =TRIM(BASE_EQUIPOS!N13) | B13: =BASE_EQUIPOS!A13 | C13: =BASE_EQUIPOS!B13 | D13: =BASE_EQUIPOS!D13 | E13: =BASE_EQUIPOS!G13 | F13: =BASE_EQUIPOS!H13 | G13: =BASE_EQUIPOS!M13 | I13: 03/015357
... A3993: =TRIM(BASE_EQUIPOS!N3993) | B3993: =BASE_EQUIPOS!A3993 | C3993: =BASE_EQUIPOS!B3993 | D3993: =BASE_EQUIPOS!D3993 | E3993: =BASE_EQUIPOS!G3993 | F3993: =BASE_EQUIPOS!H3993 | G3993: =BASE_EQUIPOS!M3993 | I3993: 07/000586
A3994: =TRIM(BASE_EQUIPOS!N3994) | B3994: =BASE_EQUIPOS!A3994 | C3994: =BASE_EQUIPOS!B3994 | D3994: =BASE_EQUIPOS!D3994 | E3994: =BASE_EQUIPOS!G3994 | F3994: =BASE_EQUIPOS!H3994 | G3994: =BASE_EQUIPOS!M3994
A3995: =TRIM(BASE_EQUIPOS!N3995) | B3995: =BASE_EQUIPOS!A3995 | C3995: =BASE_EQUIPOS!B3995 | D3995: =BASE_EQUIPOS!D3995 | E3995: =BASE_EQUIPOS!G3995 | F3995: =BASE_EQUIPOS!H3995 | G3995: =BASE_EQUIPOS!M3995
A3996: =TRIM(BASE_EQUIPOS!N3996) | B3996: =BASE_EQUIPOS!A3996 | C3996: =BASE_EQUIPOS!B3996 | D3996: =BASE_EQUIPOS!D3996 | E3996: =BASE_EQUIPOS!G3996 | F3996: =BASE_EQUIPOS!H3996 | G3996: =BASE_EQUIPOS!M3996
A3997: =TRIM(BASE_EQUIPOS!N3997) | B3997: =BASE_EQUIPOS!A3997 | C3997: =BASE_EQUIPOS!B3997 | D3997: =BASE_EQUIPOS!D3997 | E3997: =BASE_EQUIPOS!G3997 | F3997: =BASE_EQUIPOS!H3997 | G3997: =BASE_EQUIPOS!M3997
A3998: =TRIM(BASE_EQUIPOS!N3998) | B3998: =BASE_EQUIPOS!A3998 | C3998: =BASE_EQUIPOS!B3998 | D3998: =BASE_EQUIPOS!D3998 | E3998: =BASE_EQUIPOS!G3998 | F3998: =BASE_EQUIPOS!H3998 | G3998: =BASE_EQUIPOS!M3998
A3999: =TRIM(BASE_EQUIPOS!N3999) | B3999: =BASE_EQUIPOS!A3999 | C3999: =BASE_EQUIPOS!B3999 | D3999: =BASE_EQUIPOS!D3999 | E3999: =BASE_EQUIPOS!G3999 | F3999: =BASE_EQUIPOS!H3999 | G3999: =BASE_EQUIPOS!M3999
A4000: =TRIM(BASE_EQUIPOS!N4000) | B4000: =BASE_EQUIPOS!A4000 | C4000: =BASE_EQUIPOS!B4000 | D4000: =BASE_EQUIPOS!D4000 | E4000: =BASE_EQUIPOS!G4000 | F4000: =BASE_EQUIPOS!H4000 | G4000: =BASE_EQUIPOS!M4000
A4001: =TRIM(BASE_EQUIPOS!N4001) | B4001: =BASE_EQUIPOS!A4001 | C4001: =BASE_EQUIPOS!B4001 | D4001: =BASE_EQUIPOS!D4001 | E4001: =BASE_EQUIPOS!G4001 | F4001: =BASE_EQUIPOS!H4001 | G4001: =BASE_EQUIPOS!M4001
A4002: =TRIM(BASE_EQUIPOS!N4002) | B4002: =BASE_EQUIPOS!A4002 | C4002: =BASE_EQUIPOS!B4002 | D4002: =BASE_EQUIPOS!D4002 | E4002: =BASE_EQUIPOS!G4002 | F4002: =BASE_EQUIPOS!H4002 | G4002: =BASE_EQUIPOS!M4002
A4003: =TRIM(BASE_EQUIPOS!N4003) | B4003: =BASE_EQUIPOS!A4003 | C4003: =BASE_EQUIPOS!B4003 | D4003: =BASE_EQUIPOS!D4003 | E4003: =BASE_EQUIPOS!G4003 | F4003: =BASE_EQUIPOS!H4003 | G4003: =BASE_EQUIPOS!M4003
A4004: =TRIM(BASE_EQUIPOS!N4004) | B4004: =BASE_EQUIPOS!A4004 | C4004: =BASE_EQUIPOS!B4004 | D4004: =BASE_EQUIPOS!D4004 | E4004: =BASE_EQUIPOS!G4004 | F4004: =BASE_EQUIPOS!H4004 | G4004: =BASE_EQUIPOS!M4004
A4005: =TRIM(BASE_EQUIPOS!N4005) | B4005: =BASE_EQUIPOS!A4005 | C4005: =BASE_EQUIPOS!B4005 | D4005: =BASE_EQUIPOS!D4005 | E4005: =BASE_EQUIPOS!G4005 | F4005: =BASE_EQUIPOS!H4005 | G4005: =BASE_EQUIPOS!M4005
... A5568: =TRIM(BASE_EQUIPOS!N5568) | B5568: =BASE_EQUIPOS!A5568 | C5568: =BASE_EQUIPOS!B5568 | D5568: =BASE_EQUIPOS!D5568 | E5568: =BASE_EQUIPOS!G5568 | F5568: =BASE_EQUIPOS!H5568 | G5568: =BASE_EQUIPOS!M5568
